Workbook

Sheet Read me
A1: SOC 2 readiness control matrix - Quillfield Systems Inc.
A2: Simulated scenario for a learning and portfolio project. Quillfield is fictional; no real company, client or audit is represented.
A3: Scope: Security (CC1-CC9) and Confidentiality (C1), AICPA 2017 Trust Services Criteria. Status as of October 16, 2026 (simulated).
A4: ISO refs are ISO/IEC 27001:2022 Annex A (main clauses cited where no Annex A control applies). NIST CSF 2.0 refs are at category level.
A5: Scoring: Implemented = 2, Partial = 1, Missing = 0. Summary sheet uses live formulas; change a state on the Controls sheet and the score updates.

Sheet Controls
A1: Control ID | B1: Domain | C1: Control description | D1: TSC criteria | E1: ISO 27001:2022 ref | F1: NIST CSF 2.0 ref | G1: Owner role | H1: Frequency | I1: Evidence expected | J1: Current state | K1: Gap notes | L1: Gap ref | M1: Risk ref
A2: GOV-01 | B2: Control environment and communication | C2: Information security policy set (access control, change management, vendor risk, incident response, data classification, acceptable use) is approved by the CTO and CEO, published in Confluence and reviewed at least annually. | D2: CC2.2; CC5.2; CC5.3 | E2: A.5.1; A.5.37 | F2: GV.PO | G2: Director, IT & Security | H2: Annual | I2: Approved policies with version history and approver; Confluence page; annual review log | J2: Partial | K2: 14 policies drafted in 2024 from a template. 3 approved by the CTO (Mar 2024), 11 never approved, none reviewed since. Several refer to tools no longer used (e.g., on-prem VPN). | L2: G-01 | M2: R-15
A3: GOV-02 | B3: Control environment and communication | C3: Code of conduct, acceptable use policy and confidentiality agreement are signed at hire (employees and contractors). The handbook describes the disciplinary process for violations. | D3: CC1.1; CC1.5; C1.1 | E3: A.5.10; A.6.2; A.6.4; A.6.6 | F3: GV.RR | G3: People Operations Manager | H3: At hire | I3: Signed offer letters and contractor agreements with confidentiality clause; BambooHR e-signature report; handbook section on discipline | J3: Implemented | K3: 10 of 10 sampled 2026 hires signed before start. No annual re-acknowledgement; recommended, not a blocker.
A4: GOV-03 | B4: Control environment and communication | C4: Leadership receives a quarterly security and compliance update (risk register, open findings, incidents, SOC 2 status) with decisions and owners recorded in minutes. The board receives an annual summary. | D4: CC1.2; CC2.2; CC4.2 | E4: A.5.4; Cl. 9.3 | F4: GV.OV | G4: CTO | H4: Quarterly | I4: Agenda, slides and minutes; action log; board pack extract | J4: Missing | K4: Security is discussed ad hoc in the weekly leadership meeting. No standing agenda item or minutes. June 2026 board pack mentions SOC 2 only as a sales item. | L4: G-01 | M4: R-15
A5: GOV-04 | B5: Control environment and communication | C5: Org chart is maintained in BambooHR and security responsibilities are written into job descriptions for the Director, IT & Security, Security Engineer, IT Administrator and DevOps Lead. | D5: CC1.3 | E5: A.5.2 | F5: GV.RR | G5: People Operations Manager | H5: On change; reviewed annually | I5: Org chart export; job descriptions for security roles | J5: Implemented | K5: Org chart current as of Sep 30, 2026. Control owner assignments in this matrix still need leadership sign-off (see GOV-03).
A6: GOV-05 | B6: Control environment and communication | C6: Security and confidentiality commitments are communicated to customers through the MSA, DPA and public trust page. Customers and third parties can report security issues to security@ or the support portal. | D6: CC2.3; C1.1 | E6: A.5.31; A.6.8 | F6: GV.OC | G6: Controller | H6: Annual; on contract change | I6: MSA and DPA templates; trust page; security@ mailbox routing; sample customer communication | J6: Implemented | K6: security@ routes to a shared mailbox monitored by the Security Engineer. Trust page lists 5 subprocessors (see VND-02).
A7: HR-01 | B7: Control environment and communication | C7: Background checks (criminal record and references) are completed before the start date for employees. Staffing agencies attest to equivalent checks for agency contractors. | D7: CC1.4 | E7: A.6.1 | F7: GV.RR | G7: People Operations Manager | H7: At hire | I7: Background check completion report; agency contract clause | J7: Implemented | K7: 10 of 10 sampled 2026 hires checked before start. The offshore QA firm is contracted directly and is covered under VND-02, not here.
A8: HR-02 | B8: Control environment and communication | C8: Security awareness training is completed within 30 days of hire and annually by all workforce members, including contractors. Phishing simulations run quarterly. Non-completion is escalated to managers. | D8: CC1.4; CC2.2 | E8: A.6.3 | F8: PR.AT | G8: Security Engineer | H8: At hire; annual; quarterly phishing | I8: Completion report by person; phishing campaign results; escalation emails | J8: Partial | K8: 2026 completion 71% (96 of 135). Contractors not enrolled. August 2026 phishing click rate 14%. No escalation of non-completion. | L8: G-02 | M8: R-02
A9: RISK-01 | B9: Risk assessment and monitoring | C9: An annual risk assessment identifies threats to service commitments, including fraud risk and risks from significant changes (new products, vendors, staff). Risks are scored, owned and tracked in a risk register reviewed quarterly, and controls are selected to address them. | D9: CC3.1; CC3.2; CC3.3; CC3.4; CC5.1 | E9: Cl. 6.1.2; Cl. 8.2 (no direct Annex A control) | F9: GV.RM; ID.RA | G9: Director, IT & Security | H9: Annual; register reviewed quarterly | I9: Risk assessment report; risk register with owners and target dates; leadership approval | J9: Missing | K9: No documented risk assessment. The risk register in this project is a first draft and needs leadership review and acceptance. | L9: G-01 | M9: R-15
A10: RISK-02 | B10: Risk assessment and monitoring | C10: An inventory of information assets (Azure resources, endpoints, SaaS applications and data stores holding customer data) is maintained with an owner and classification for each item. | D10: CC2.1; CC3.2; CC6.1 | E10: A.5.9 | F10: ID.AM | G10: IT Administrator | H10: Continuous; reconciled quarterly | I10: Azure Resource Graph export; Intune device list; SaaS register; data store list with classification | J10: Partial | K10: Azure and Intune inventories are system-generated and complete. No SaaS register: Defender for Cloud Apps discovery shows 74 apps in use, 19 sanctioned. Customer data stores are not tagged with owner or classification. | L10: G-08 | M10: R-13
A11: MON-01 | B11: Risk assessment and monitoring | C11: Control owners complete a quarterly self-assessment against this control matrix. Exceptions and deficiencies are logged, assigned and tracked to closure, and reported to leadership through GOV-03. | D11: CC4.1; CC4.2 | E11: A.5.35; A.5.36; Cl. 9.2 | F11: GV.OV; ID.IM | G11: Director, IT & Security | H11: Quarterly | I11: Self-assessment results; deficiency log with status and dates; evidence of reporting | J11: Missing | K11: No monitoring of controls today. A tracker (Jira project or GRC tool) is needed before the Type I date. | L11: G-01 | M11: R-15
A12: MON-02 | B12: Risk assessment and monitoring | C12: An independent penetration test of the production application and external perimeter is performed annually. Findings are tracked in Jira and retested. | D12: CC4.1; CC7.1 | E12: A.8.8; A.8.29 | F12: ID.RA; ID.IM | G12: Director, IT & Security | H12: Annual | I12: Pen test report and scope letter; Jira tickets for findings; retest letter | J12: Partial | K12: February 2026 test: 2 high, 5 medium. High IDOR on invoice export was fixed and retested. High stored XSS in the payee notes field is still open (about 240 days). No retest booked. | L12: G-09 | M12: R-06
A13: AC-01 | B13: Logical and physical access | C13: Workforce access to in-scope systems (Azure portal, M365, GitHub Enterprise, Jira/Confluence, Zendesk, internal admin console) uses Entra ID SSO with unique named accounts. Generic or shared accounts are prohibited unless approved and assigned an owner. | D13: CC6.1 | E13: A.5.16; A.8.5 | F13: PR.AA | G13: IT Administrator | H13: Continuous | I13: SSO configuration per application; Entra enterprise application list; register of approved generic accounts with owners | J13: Partial | K13: SSO in place for all listed apps except the Zendesk admin account (local login, shared by 3 support leads). 9 generic accounts in Entra (e.g., support@, finance-ap@, training01) have sign-in enabled and no named owner. | L13: G-04 | M13: R-01
A14: AC-02 | B14: Logical and physical access | C14: Conditional Access enforces MFA for all users and all cloud apps. Administrators require phishing-resistant MFA. Exclusions are limited to two break-glass accounts whose sign-ins raise an alert. | D14: CC6.1 | E14: A.8.5; A.5.17 | F14: PR.AA | G14: Director, IT & Security | H14: Continuous; exclusions reviewed quarterly | I14: Conditional Access policy export; exclusion group membership; Sentinel alert rule for break-glass sign-in | J14: Partial | K14: 'Require MFA - all users' excludes group CA-Exclusions (7 members): 2 break-glass accounts (acceptable), 4 user accounts used as service accounts, and the CFO (excluded since 2024 for a travel issue). No phishing-resistant requirement for admins. No break-glass alert. | L14: G-06 | M14: R-02
A15: AC-03 | B15: Logical and physical access | C15: Access to in-scope systems is granted only through a Jira Service Management request approved by the manager (and by the system owner for privileged roles). Access is granted through role-based Entra groups. | D15: CC6.2; CC6.3 | E15: A.5.15; A.5.18 | F15: PR.AA | G15: IT Administrator | H15: Per request | I15: Population of access grants for the period; sampled tickets with approvals; group-to-role mapping | J15: Partial | K15: 25 grants sampled (Apr-Sep 2026): 16 with ticket and approval, 6 approved in Teams chat only, 3 with no evidence of approval. | L15: G-05 | M15: R-01
A16: AC-04 | B16: Logical and physical access | C16: Leavers' Entra accounts are disabled within 1 business day of the termination date, triggered by BambooHR. Access to non-SSO apps and the GitHub organization is removed the same day. Contractor end dates are tracked and actioned the same way. | D16: CC6.2; CC6.3 | E16: A.5.18; A.6.5 | F16: PR.AA | G16: IT Administrator | H16: Per termination | I16: BambooHR termination report; Entra audit log of disable events; offboarding tickets; contractor roster with end dates | J16: Partial | K16: 14 employee leavers (Apr-Sep 2026): 11 disabled within 1 business day, 1 after 4 days, 2 still enabled at review (37 and 58 days after termination; no sign-ins after termination in Sentinel SigninLogs). 1 leaver stayed in the GitHub org for 23 days. Contractors are not in BambooHR; 6 former contractors still enabled. | L16: G-04 | M16: R-01
A17: AC-05 | B17: Logical and physical access | C17: Quarterly user access review covering Entra privileged roles, Azure RBAC on the production subscription, GitHub org and teams, Azure SQL logins, Zendesk and the internal admin console. System owners certify each user; IT confirms the population is complete and removes access within 5 business days; the signed review is retained. | D17: CC6.2; CC6.3 | E17: A.5.18; A.8.2 | F17: PR.AA | G17: Director, IT & Security (coordinator); system owners (reviewers) | H17: Quarterly | I17: System-generated user listings with extraction date and parameters; completeness check; reviewer sign-off; removal tickets | J17: Missing | K17: No review in 2026. A November 2025 Azure RBAC review was a spreadsheet with no reviewer sign-off and no evidence the changes were made. First review must be completed in Q4 2026 so one full cycle exists before the Type I date. | L17: G-03 | M17: R-01; R-03; R-11
A18: AC-06 | B18: Logical and physical access | C18: Privileged and non-human identities: Entra and Azure privileged roles are eligible-only through Privileged Identity Management (PIM) with approval and justification. Global Administrators are limited to 4 plus break-glass. Service principal secrets are stored in Key Vault, expire within 12 months and have a named owner; workload identity federation is preferred. | D18: CC6.1; CC6.3 | E18: A.8.2; A.5.17 | F18: PR.AA | G18: Director, IT & Security | H18: Continuous; reviewed in AC-05 | I18: PIM role settings; role assignment export; app registration credential report | J18: Partial | K18: Entra ID P2 is licensed but PIM is not used: 5 permanent Global Admins plus 2 break-glass; 4 Owners and 7 Contributors with standing access to the production subscription. 31 app registrations: 12 use client secrets, 5 valid for more than 12 months, 2 expired but not removed, 4 with no owner. GitHub Actions already uses OIDC. | L18: G-06 | M18: R-03
A19: AC-07 | B19: Logical and physical access | C19: Segregation of duties: a documented SoD matrix lists conflicting roles (code author vs. approver vs. deployer; access requester vs. approver; editing customer payee bank details vs. approving the edit). Conflicts are prevented by system configuration or mitigated by a documented review. | D19: CC5.1; CC6.3 | E19: A.5.3 | F19: PR.AA | G19: VP Engineering | H19: Annual; checked in AC-05 | I19: SoD matrix; configuration showing enforcement; conflict report and mitigating review | J19: Missing | K19: No SoD matrix. Production deployment environment does not have 'prevent self-review' enabled: 3 of 25 deployments approved by the person who triggered them. Tier 2 support can edit customers' payee bank details in the internal admin console with no second approval; edits are logged in the app audit table but nobody reviews them. | L19: G-07 | M19: R-04; R-05
A20: AC-08 | B20: Logical and physical access | C20: Physical security of production is provided by Microsoft Azure as a carved-out subservice organization, relied on through the annual SOC 2 report review (VND-03). The Toronto office uses badge access and holds no servers or customer data. | D20: CC6.4 | E20: A.7.1; A.7.2; A.5.23 | F20: PR.AA | G20: IT Administrator | H20: Annual | I20: Azure SOC 2 report and review memo (VND-03); badge system user list; confirmation of no on-premises servers | J20: Implemented | K20: Design is appropriate for a cloud-only company. Reliance on Azure must be evidenced through VND-03.
A21: AC-09 | B21: Logical and physical access | C21: Returned or retired laptops are wiped through Intune, or the disk is destroyed by a certified vendor, before reuse or disposal. A record is kept by serial number. | D21: CC6.5 | E21: A.7.14; A.8.10 | F21: PR.DS | G21: IT Administrator | H21: Per device | I21: Intune wipe log; certificates of destruction; asset register status | J21: Implemented | K21: 12 devices retired in 2026, all with a wipe log entry or certificate of destruction.
A22: AC-10 | B22: Logical and physical access | C22: Production network: Azure SQL and Storage use private endpoints; NSGs deny inbound traffic by default; public traffic reaches the app only through Azure Front Door with WAF in prevention mode; no management ports are open to the internet. | D22: CC6.6 | E22: A.8.20; A.8.22 | F22: PR.IR | G22: DevOps Lead | H22: Continuous; reviewed quarterly | I22: Network diagram; NSG rule export; Front Door WAF policy; Tenable external scan | J22: Implemented | K22: Observation: Tenable external scan found a staging jump host with RDP (3389) open to the internet; closed Oct 7, 2026. Recommend an Azure Policy deny rule for internet-facing management ports. | M22: R-06
A23: AC-11 | B23: Logical and physical access | C23: Customer data is encrypted in transit (TLS 1.2 or higher) and at rest (Azure SQL TDE; Storage encryption with customer-managed keys in Key Vault). Key Vault access is restricted and logged. | D23: CC6.1; CC6.7; C1.1 | E23: A.8.24 | F23: PR.DS | G23: DevOps Lead | H23: Continuous | I23: TLS scan results; TDE and storage encryption settings; Key Vault RBAC and diagnostic settings | J23: Implemented | K23: Confirmed from configuration screenshots. Minimum TLS 1.2 set on Storage and SQL. Key Vault logs are not yet in Sentinel (see OPS-02).
A24: AC-12 | B24: Logical and physical access | C24: Corporate endpoints are enrolled in Intune with a compliance policy (disk encryption, OS patch level, screen lock) and onboarded to Defender for Endpoint. Conditional Access blocks non-compliant devices from M365 and the Azure portal. | D24: CC6.7; CC6.8 | E24: A.8.1; A.8.7 | F24: PR.PS | G24: IT Administrator | H24: Continuous | I24: Intune compliance report; Defender device inventory; Conditional Access policy requiring a compliant device | J24: Partial | K24: 128 Intune devices: 9 non-compliant (OS updates older than 30 days); 7 macOS developer laptops not onboarded to Defender. The 14 contractors are excluded from the compliant-device policy and use unmanaged devices with full M365 web access. | L24: G-08 | M24: R-13; R-14
A25: OPS-01 | B25: System operations | C25: Vulnerability and configuration management: Tenable scans Azure VMs and the external surface weekly; Defender for Cloud assesses container images and Azure configuration against the Microsoft cloud security benchmark. Findings are fixed within SLA (critical 15 days, high 30 days) or have an approved exception. | D25: CC7.1 | E25: A.8.8; A.8.9 | F25: ID.RA; PR.PS | G25: Security Engineer | H25: Weekly scans; monthly SLA report | I25: Scan schedules; vulnerability ageing report; secure score history; exception register | J25: Partial | K25: Scanning is in place but no SLA is defined. 27 critical and 64 high findings open; 18 criticals older than 30 days (oldest 112 days). Defender for Cloud secure score 58%. No exception process. | L25: G-09 | M25: R-06; R-14
A26: OPS-02 | B26: System operations | C26: Security logs from Entra ID, Azure Activity, Key Vault, AKS, Azure SQL auditing, M365, Defender XDR and the GitHub audit log are sent to Microsoft Sentinel and retained for at least 12 months. | D26: CC7.2 | E26: A.8.15 | F26: PR.PS; DE.CM | G26: Security Engineer | H26: Continuous; connector health reviewed monthly | I26: Sentinel data connector list; Log Analytics retention settings; sample queries showing recent ingestion | J26: Partial | K26: Connected: Entra ID, Azure Activity, Defender XDR, Defender for Cloud, M365. Not connected: GitHub audit log, AKS control plane logs, Key Vault diagnostics. Workspace retention is 90 days; the draft enterprise MSA requires 12 months. | L26: G-10 | M26: R-07
A27: OPS-03 | B27: System operations | C27: Sentinel analytics rules and Defender XDR alerts create incidents that the security on-call triages within 4 business hours for high severity. Triage notes and the closure reason are recorded. | D27: CC7.2; CC7.3 | E27: A.8.16; A.5.25 | F27: DE.CM; DE.AE | G27: Security Engineer | H27: Continuous | I27: Incident export with timestamps and closure comments; on-call schedule; analytics rule list | J27: Partial | K27: 312 incidents Jul-Sep 2026: median time to acknowledge 19 hours; 61% closed with no comment; no after-hours coverage. Mostly default rules; none for payee bank detail edits in the admin console. | L27: G-10 | M27: R-04; R-07
A28: OPS-04 | B28: System operations | C28: The incident response plan defines severity levels, roles, escalation, evidence handling, customer notification (72 hours per MSA) and PIPEDA breach assessment, reporting and record-keeping. The plan is tested by an annual tabletop and post-incident reviews are completed for Sev 1 and 2 incidents. | D28: CC7.3; CC7.4; CC7.5 | E28: A.5.24; A.5.25; A.5.26; A.5.27; A.5.28 | F28: RS.MA; RS.AN; RS.CO; RS.MI; RC.RP | G28: Director, IT & Security | H28: Annual review and tabletop; review per incident | I28: Approved IR plan; tabletop report; incident tickets; post-incident review; breach record log | J28: Partial | K28: IR plan v0.3 (Confluence, 2025) is unapproved and untested. The May 2026 mailbox compromise (account executive, phishing) was handled ad hoc: no post-incident review, no documented assessment of whether it was a breach of security safeguards under PIPEDA, no breach record. | L28: G-11 | M28: R-08
A29: OPS-05 | B29: System operations | C29: Azure SQL point-in-time restore (35 days) and long-term retention (monthly, 12 months) on geo-redundant storage; Blob versioning and soft delete enabled. Restores are tested twice a year and the results documented. | D29: CC7.5; CC9.1 | E29: A.8.13; A.8.14 | F29: PR.DS; RC.RP | G29: DevOps Lead | H29: Continuous; restore test semi-annual | I29: Backup policy configuration; restore test record with time taken and data point restored | J29: Partial | K29: Point-in-time restore at the 7-day default; no long-term retention; geo-redundant storage enabled. Blob soft delete 7 days, versioning off. No restore test has ever been documented. | L29: G-12 | M29: R-09; R-14
A30: CHG-01 | B30: Change management | C30: Production changes are raised as Jira tickets linked to the pull request and classified as standard, normal or emergency. Emergency changes are reviewed and approved retrospectively within 2 business days. | D30: CC8.1 | E30: A.8.32 | F30: PR.PS | G30: VP Engineering | H30: Per change | I30: Change population (merged PRs and deployments); linked Jira tickets; emergency change log | J30: Partial | K30: No written process. 19 of 25 sampled PRs (76%) linked to a Jira ticket. No emergency category: hotfixes look the same as normal changes. | L30: G-13 | M30: R-05
A31: CHG-02 | B31: Change management | C31: Branch protection on the default branch of every production repository requires a pull request, at least one approving review from someone other than the author, passing status checks, and no administrator bypass. | D31: CC8.1 | E31: A.8.32; A.8.4 | F31: PR.PS | G31: DevOps Lead | H31: Continuous; settings reviewed quarterly | I31: Ruleset or branch protection export per repo; list of bypass actors; sampled PRs | J31: Partial | K31: Rulesets on app-api and app-web meet the standard. platform-infra (Terraform for production) has no branch protection, and 3 of 25 sampled PRs were merged without review, all in that repo. 4 org owners can bypass rulesets. | L31: G-13 | M31: R-05
A32: CHG-03 | B32: Change management | C32: Deployments to production run only through GitHub Actions using OIDC federation. The 'production' environment requires approval from a release approver other than the person who triggered the run. Engineers have no standing write access to production, and human changes made outside the pipeline are detected and reviewed. | D32: CC8.1; CC6.1 | E32: A.8.31; A.8.32 | F32: PR.PS | G32: DevOps Lead | H32: Per deployment; out-of-band report monthly | I32: Workflow files; environment protection settings; Azure Activity log report of non-pipeline write operations | J32: Partial | K32: Pipeline design is sound, but 41 write operations were made by named users in the production resource group outside the pipeline in the last 30 days (app settings, NSG rule edits, AKS scaling). None were reviewed. Self-approval is possible (see AC-07). | L32: G-13 | M32: R-05
A33: CHG-04 | B33: Change management | C33: Secure development: CodeQL code scanning, Dependabot alerts and secret scanning with push protection are enabled on production repositories. Development, staging and production run in separate Azure subscriptions. | D33: CC8.1; CC7.1 | E33: A.8.25; A.8.28; A.8.29; A.8.31 | F33: PR.PS | G33: VP Engineering | H33: Continuous | I33: GitHub Advanced Security settings; alert dashboard; subscription structure | J33: Implemented | K33: Enabled on all 3 production repos. Observation: 11 high Dependabot alerts older than 60 days; these should fall under the OPS-01 SLA. | M33: R-06
A34: BCP-01 | B34: Risk mitigation and vendors | C34: A business continuity and disaster recovery plan covers the production platform (Canada Central primary, Canada East recovery) with defined RTO and RPO and is tested annually. Cyber insurance coverage is reviewed annually. | D34: CC9.1 | E34: A.5.29; A.5.30 | F34: PR.IR; RC.RP | G34: CTO | H34: Annual | I34: BC/DR plan; DR test report; insurance certificate | J34: Missing | K34: No BC/DR plan or test. Infrastructure is defined in Terraform, which helps a rebuild, but there is no recovery runbook. Cyber insurance is in place (renewed June 2026). | L34: G-12 | M34: R-09
A35: VND-01 | B35: Risk mitigation and vendors | C35: A vendor inventory assigns each vendor a security tier (Tier 1: customer data or production access; Tier 2: company confidential data; Tier 3: no data access) and is reconciled to the NetSuite AP vendor master quarterly. | D35: CC9.2 | E35: A.5.19 | F35: GV.SC | G35: Controller (with Director, IT & Security) | H35: Reconciled quarterly | I35: Vendor inventory with tier, owner and data types; reconciliation to AP vendor master | J35: Partial | K35: NetSuite has 214 active vendors; 23 identified in this assessment as having system or data access. Vendors are created in NetSuite with no security review step, and 4 SaaS tools are paid by corporate card so never reach the vendor master. | L35: G-14 | M35: R-10
A36: VND-02 | B36: Risk mitigation and vendors | C36: Before onboarding Tier 1 and 2 vendors, security due diligence is completed (SOC 2 report or questionnaire) and contracts include security, confidentiality, breach notification and data return/deletion terms. DPAs are in place for all subprocessors. | D36: CC9.2; C1.1 | E36: A.5.19; A.5.20 | F36: GV.SC | G36: Director, IT & Security | H36: Per new vendor; at renewal | I36: Due diligence file; signed contract or DPA; approval record | J36: Missing | K36: No due diligence process. DPAs on file for 3 of 5 public subprocessors. Missing: Atlassian (online terms accepted, not filed) and the offshore QA firm, whose MSA has an NDA but no data protection or deletion terms even though it has staging access (see CONF-03). | L36: G-14 | M36: R-10; R-11
A37: VND-03 | B37: Risk mitigation and vendors | C37: SOC 2 reports for carved-out subservice organizations and Tier 1 vendors (Microsoft Azure, GitHub, Zendesk, Twilio SendGrid, Atlassian) are obtained and reviewed annually: opinion, exceptions, period covered and bridge letters. Complementary user entity controls (CUECs) are mapped to Quillfield controls. | D37: CC9.2 | E37: A.5.22; A.5.23 | F37: GV.SC | G37: Director, IT & Security | H37: Annual | I37: Review memo per report; CUEC mapping; bridge letters | J37: Missing | K37: No vendor SOC reports on file. Without this review the system description cannot properly support the carve-out of Azure and GitHub. | L37: G-14 | M37: R-10
A38: CONF-01 | B38: Confidentiality | C38: A data classification standard (Public, Internal, Confidential, Restricted) sets handling rules. Customer invoices and payee bank data are Restricted. Microsoft Purview sensitivity labels are applied to M365 content. | D38: C1.1 | E38: A.5.12; A.5.13 | F38: ID.AM; PR.DS | G38: Director, IT & Security | H38: Reviewed annually | I38: Approved classification standard; Purview label policy; data store classification (RISK-02) | J38: Partial | K38: Draft standard exists (2024), unapproved. Purview labels are configured but not published to users. | L38: G-15 | M38: R-13
A39: CONF-02 | B39: Confidentiality | C39: Customer data is retained per contract and deleted within 90 days of contract termination. Deletion follows a runbook, is verified, and is confirmed to the customer in writing. | D39: C1.2 | E39: A.8.10; A.5.33 | F39: PR.DS | G39: VP Engineering | H39: Per termination; quarterly check of churned customers | I39: Customer termination list; deletion tickets with verification query; confirmation letters | J39: Missing | K39: No deletion process. 4 customers that left in 2024-2025 still have full data in production Azure SQL, against an MSA commitment to delete within 90 days. | L39: G-15 | M39: R-12
A40: CONF-03 | B40: Confidentiality | C40: Production customer data is not copied to non-production environments. Where realistic test data is needed it is masked or synthetic. | D40: C1.1 | E40: A.8.33; A.8.11; A.8.31 | F40: PR.DS | G40: VP Engineering | H40: Continuous | I40: Data refresh procedure; masking script; sample check of the staging database | J40: Missing | K40: Staging is refreshed monthly from a production backup with no masking. 6 staff at the offshore QA firm can access it, and it has weaker access controls (shared SQL login, no PIM). | L40: G-15 | M40: R-11
...

Sheet Summary
A1: Domain | B1: TSC | C1: Controls | D1: Implemented | E1: Partial | F1: Missing | G1: Readiness %
A2: Control environment and communication | B2: CC1-CC2 | C2: =COUNTIF(Controls!$B:$B,A2) | D2: =COUNTIFS(Controls!$B:$B,A2,Controls!$J:$J,"Implemented") | E2: =COUNTIFS(Controls!$B:$B,A2,Controls!$J:$J,"Partial") | F2: =COUNTIFS(Controls!$B:$B,A2,Controls!$J:$J,"Missing") | G2: =IF(C2=0,0,(2*D2+E2)/(2*C2))
A3: Risk assessment and monitoring | B3: CC3-CC5 | C3: =COUNTIF(Controls!$B:$B,A3) | D3: =COUNTIFS(Controls!$B:$B,A3,Controls!$J:$J,"Implemented") | E3: =COUNTIFS(Controls!$B:$B,A3,Controls!$J:$J,"Partial") | F3: =COUNTIFS(Controls!$B:$B,A3,Controls!$J:$J,"Missing") | G3: =IF(C3=0,0,(2*D3+E3)/(2*C3))
A4: Logical and physical access | B4: CC6 | C4: =COUNTIF(Controls!$B:$B,A4) | D4: =COUNTIFS(Controls!$B:$B,A4,Controls!$J:$J,"Implemented") | E4: =COUNTIFS(Controls!$B:$B,A4,Controls!$J:$J,"Partial") | F4: =COUNTIFS(Controls!$B:$B,A4,Controls!$J:$J,"Missing") | G4: =IF(C4=0,0,(2*D4+E4)/(2*C4))
A5: System operations | B5: CC7 | C5: =COUNTIF(Controls!$B:$B,A5) | D5: =COUNTIFS(Controls!$B:$B,A5,Controls!$J:$J,"Implemented") | E5: =COUNTIFS(Controls!$B:$B,A5,Controls!$J:$J,"Partial") | F5: =COUNTIFS(Controls!$B:$B,A5,Controls!$J:$J,"Missing") | G5: =IF(C5=0,0,(2*D5+E5)/(2*C5))
A6: Change management | B6: CC8 | C6: =COUNTIF(Controls!$B:$B,A6) | D6: =COUNTIFS(Controls!$B:$B,A6,Controls!$J:$J,"Implemented") | E6: =COUNTIFS(Controls!$B:$B,A6,Controls!$J:$J,"Partial") | F6: =COUNTIFS(Controls!$B:$B,A6,Controls!$J:$J,"Missing") | G6: =IF(C6=0,0,(2*D6+E6)/(2*C6))
A7: Risk mitigation and vendors | B7: CC9 | C7: =COUNTIF(Controls!$B:$B,A7) | D7: =COUNTIFS(Controls!$B:$B,A7,Controls!$J:$J,"Implemented") | E7: =COUNTIFS(Controls!$B:$B,A7,Controls!$J:$J,"Partial") | F7: =COUNTIFS(Controls!$B:$B,A7,Controls!$J:$J,"Missing") | G7: =IF(C7=0,0,(2*D7+E7)/(2*C7))
A8: Confidentiality | B8: C1 | C8: =COUNTIF(Controls!$B:$B,A8) | D8: =COUNTIFS(Controls!$B:$B,A8,Controls!$J:$J,"Implemented") | E8: =COUNTIFS(Controls!$B:$B,A8,Controls!$J:$J,"Partial") | F8: =COUNTIFS(Controls!$B:$B,A8,Controls!$J:$J,"Missing") | G8: =IF(C8=0,0,(2*D8+E8)/(2*C8))
A9: Total | C9: =SUM(C2:C8) | D9: =SUM(D2:D8) | E9: =SUM(E2:E8) | F9: =SUM(F2:F8) | G9: =(2*D9+E9)/(2*C9)
